Workbook
Name SegmentaciónDeDatos_Área: #N/A
Name SegmentaciónDeDatos_Sexo: #N/A
Name SegmentaciónDeDatos_Tipo_trabajador: #N/A

Sheet Datos
A1: Id | B1: Edad | C1: Tipo trabajador | D1: Sexo | E1: Área | F1: Estado Cita | G1: % grasa | H1: Condición %grasa | I1: Principal Padecimiento Crónico | J1: Diagnóstico Macro | K1: Diagnóstico Micro | L1: Instancia de Atención | M1: Categoria | N1: Estado | O1: Días | P1: Monto de la consulta | Q1: Monto 2 | R1: fecha | S1: Mes
A2: 60000001 | B2: 24 | C2: Privado | D2: Hombre | E2: Comercial y marketing | F2: Asistió | G2: 0.2 | H2: Normal | I2: Migraña | J2: Oftalmológico | K2: Sd de abstinencia | L2: CCSS | M2: Laboratorio | N2: No | O2: 0 | P2: 32249 | Q2: =+P2/1000000 -> 0.032249 | R2: 43252 | S2: Junio
A3: 60000002 | B3: 43 | C3: Público | D3: Mujer | E3: Administración | F3: Asistió | G3: 0.32 | H3: Obeso | I3: Tiroides | J3: Circulatorio | K3: Solicitud | L3: CCSS | M3: Laboratorio | N3: No | O3: 0 | P3: 50190 | Q3: =+P3/1000000 -> 0.05019 | R3: 43252 | S3: Junio
A4: 60000003 | B4: 38 | C4: Privado | D4: Hombre | E4: Contabilidad y finanzas | F4: Asistió | G4: 0.2 | H4: Normal | I4: Tiroides | J4: IVRS | K4: Liumbalgia | L4: CCSS | M4: Laboratorio | N4: No | O4: 3 | P4: 53861 | Q4: =+P4/1000000 -> 0.053861 | R4: 43252 | S4: Junio
A5: 60000004 | B5: 40 | C5: Privado | D5: Hombre | E5: Logística | F5: Asistió | G5: 0.23 | H5: Normal | I5: Hipotiroidismo | J5: Respiratorio | K5: Reflujo gastroesofágico | L5: CCSS | M5: Laboratorio | N5: No | O5: 0 | P5: 63985 | Q5: =+P5/1000000 -> 0.063985 | R5: 43252 | S5: Junio
A6: 60000005 | B6: 61 | C6: Privado | D6: Mujer | E6: Administración | F6: Asistió | G6: 0.36 | H6: Obeso | I6: Espasticidad | J6: Ginecológico | K6: Tapon de cerumen | L6: CCSS | M6: Laboratorio | N6: No | O6: 2 | P6: 71975 | Q6: =+P6/1000000 -> 0.071975 | R6: 43252 | S6: Junio
A7: 60000006 | B7: 27 | C7: Privado | D7: Hombre | E7: Administración | F7: Asistió | G7: 0.38 | H7: Obeso | I7: Depresión | J7: Geniunitario | K7: Cefalea | L7: CCSS | M7: Laboratorio | N7: No | O7: 0 | P7: 38682 | Q7: =+P7/1000000 -> 0.038682 | R7: 43252 | S7: Junio
A8: 60000007 | B8: 27 | C8: Privado | D8: Mujer | E8: Gerencia | F8: Asistió | G8: 0.13 | H8: Delgado | I8: Bipolar | J8: Ginecológico | K8: Fasceitis plantar | L8: CCSS | M8: Laboratorio | N8: No | O8: 0 | P8: 69924 | Q8: =+P8/1000000 -> 0.069924 | R8: 43252 | S8: Junio
A9: 60000008 | B9: 58 | C9: Privado | D9: Mujer | E9: Gerencia | F9: Asistió | G9: 0.18 | H9: Delgado | I9: Gastritis | J9: Respiratorio | K9: Sd de abstinencia | L9: CCSS | M9: Laboratorio | N9: No | O9: 3 | P9: 41810 | Q9: =+P9/1000000 -> 0.04181 | R9: 43252 | S9: Junio
A10: 60000009 | B10: 33 | C10: Privado | D10: Mujer | E10: Asesoría | F10: Asistió | G10: 0.38 | H10: Obeso | I10: Ninguno | J10: Oftalmológico | K10: Sinusitis | L10: CCSS | M10: Laboratorio | N10: No | O10: 7 | P10: 56001 | Q10: =+P10/1000000 -> 0.056001 | R10: 43252 | S10: Junio
A11: 60000010 | B11: 34 | C11: Privado | D11: Mujer | E11: Gerencia | F11: Asistió | G11: 0.21 | H11: Normal | I11: Bipolar | J11: Osteomuscular | K11: Herpes labial | L11: CCSS | M11: Laboratorio | N11: No | O11: 0 | P11: 41600 | Q11: =+P11/1000000 -> 0.0416 | R11: 43252 | S11: Junio
A12: 60000011 | B12: 49 | C12: Privado | D12: Mujer | E12: Comercial y marketing | F12: Asistió | G12: 0.18 | H12: Delgado | I12: Osteoporosis | J12: Consulta general | K12: Solicitud de equipo ergonomico | L12: CCSS | M12: Laboratorio | N12: No | O12: 0 | P12: 62931 | Q12: =+P12/1000000 -> 0.062931 | R12: 43252 | S12: Junio
A13: 60000012 | B13: 31 | C13: Privado | D13: Hombre | E13: Otros | F13: Asistió | G13: 0.16 | H13: Delgado | I13: Bipolar | J13: Dermatológico | K13: Migraña | L13: CCSS | M13: Laboratorio | N13: No | O13: 0 | P13: 67313 | Q13: =+P13/1000000 -> 0.067313 | R13: 43252 | S13: Junio
... A2537: 60000634 | B2537: 28 | C2537: Privado | D2537: Mujer | E2537: Administración | F2537: Recargo | G2537: 0.15 | H2537: Delgado | I2537: Tiroides | J2537: Geniunitario | K2537: Rinitis | L2537: CCSS | M2537: Incapacidad | N2537: No | O2537: 0 | P2537: 75919 | Q2537: =+P2537/1000000 -> 0.075919 | R2537: 43252 | S2537: Junio
P2541: =+AVERAGE(P2:P2537) -> 54353.271

Sheet Análisis (2)
A1: Datos pregunta a | E1: Datos pregunta b | H1: Datos pregunta c | K1: Datos pregunta d | Q1: Datos pregunta e | U1: Segmentadores
A2: Datos a resaltar | E2: Demografía de la población
H3: Area de trabajo | K3: Top 5 Padecimientos crónicos | Q3: Intsancia de atencion | U3: Tipo de trabajador
A4: Monto promedio Consulta | E4: Sexo | K4: Mes | L4: Junio | Q4: Etiquetas de fila | R4: Cuenta de Mes | U4: Sexo
A5: Promedio de Monto de la consulta | E5: Etiquetas de fila | F5: Cuenta de Mes | H5: Área | I5: Cantidad de servicios | Q5: CCSS | R5: 0.54716981 | U5: Área de trabajo
A6: 52915.226 | E6: Hombre | F6: 0.49056604 | H6: Recursos Humanos | I6: 212 | K6: Etiquetas de fila | L6: Cuenta de Mes | Q6: Clínica Bíblica | R6: 0.13207547
E7: Mujer | F7: 0.50943396 | H7: Total | I7: 212 | K7: Bipolar | L7: 28 | Q7: INS | R7: 0.32075472
E8: Total general | F8: 1 | K8: Tiroides | L8: 20 | Q8: Total general | R8: 1
A9: Incapacidades promedio en días | E9: | | K9: Asma y Rinitis | L9: 20
A10: Categoria | B10: Incapacidad | K10: Hipertensión | L10: 16
A11: Estado | B11: Si | E11: Trabajador | K11: Hipotiroidismo | L11: 16 | Q11: Recuento de servicios adicionales Brindados
A12: Incapacidades promedio en días | E12: Etiquetas de fila | F12: Cuenta de Mes | K12: Dermatitis | L12: 16
A13: Promedio de Días | E13: Privado | F13: 0.41509434 | K13: Rinitis | L13: 12
A14: 3.64 | E14: Público | F14: 0.58490566 | K14: Migraña | L14: 12 | Q14: Cuenta de Mes | R14: Etiquetas de columna
E15: Total general | F15: 1 | K15: Asma | L15: 12 | Q15: Etiquetas de fila | R15: No | S15: Si | T15: Total general
K16: Artritis Reumatoide | L16: 12 | Q16: Consulta adicional | R16: 31 | S16: 22 | T16: 53
K17: Gastritis | L17: 12 | Q17: Incapacidad | R17: 28 | S17: 25 | T17: 53
E18: Edad | K18: Lumbalgia | L18: 8 | Q18: Laboratorio | R18: 31 | S18: 22 | T18: 53
E19: Etiquetas de fila | F19: Cuenta de Mes | K19: Depresión | L19: 8 | Q19: Rayos "X" | R19: 36 | S19: 17 | T19: 53
E20: 20 | F20: 4 | K20: Espasticidad | L20: 8 | Q20: Total general | R20: 126 | S20: 86 | T20: 212
E21: 22 | F21: 8 | K21: Osteoporosis | L21: 8
E22: 29 | F22: 8 | H22: Citas | K22: Ninguno | L22: 4
E23: 30 | F23: 4 | H23: Etiquetas de fila | I23: Cuenta de Mes | K23: Total general | L23: 212
E24: 31 | F24: 4 | H24: Asistió | I24: 188
E25: 32 | F25: 8 | H25: Ausente | I25: 16
E26: 33 | F26: 4 | H26: Recargo | I26: 8 | K26: Top 5 Diagnóstico Micro
E27: 34 | F27: 8 | H27: Total general | I27: 212 | K27: Mes | L27: Junio
E28: 35 | F28: 12
E29: 36 | F29: 8 | H29: Condición grasa | K29: Etiquetas de fila | L29: Cuenta de Mes
E30: 37 | F30: 8 | H30: Etiquetas de fila | I30: Cuenta de Mes | K30: Solicitud | L30: 20
E31: 40 | F31: 4 | H31: Atleta | I31: 0.075471698 | K31: Sinusitis | L31: 12
E32: 44 | F32: 4 | H32: Corpulento | I32: 0.094339623 | K32: Migraña | L32: 8
E33: 45 | F33: 8 | H33: Delgado | I33: 0.1509434 | K33: Reflujo gastroesofágico | L33: 8
E34: 46 | F34: 12 | H34: Normal | I34: 0.22641509 | K34: Picadura de insecto | L34: 8
E35: 47 | F35: 8 | H35: Obeso | I35: 0.45283019 | K35: Blefaritis | L35: 8
E36: 48 | F36: 8 | H36: Total general | I36: 1 | K36: Solicitud del uso del asensor | L36: 8
E37: 49 | F37: 4 | K37: Contractura mm | L37: 8
E38: 50 | F38: 8 | K38: Nauseas | L38: 8
E39: 52 | F39: 4 | H39: Porcentaje grasa promedio | K39: Dismenorrea | L39: 8
E40: 54 | F40: 16 | H40: Promedio de % grasa | K40: Dolor por pieza dental | L40: 8
...

Sheet Hoja3
A1: Información demográfica | K1: Características del Área de trabajo
N5: Porcentaje de grasa Promedio
N7: =+GETPIVOTDATA("% grasa",'Análisis (2)'!$H$40) -> 0.26301887
A15: Top Enfermedades en Junio | K15: Características del Área de trabajo
A17: Padecimientos crónicos | D17: Diagnóstico Micro | H17: Diagnóstico Macro
A18: Padecimiento | B18: Cantidad | D18: Diagnóstico | E18: Cantidad | H18: Diagnóstico | I18: Cantidad
A19: =+'Análisis (2)'!K7 -> Bipolar | B19: =+'Análisis (2)'!L7 -> 28 | D19: =+'Análisis (2)'!K30 -> Solicitud | E19: =+'Análisis (2)'!L30 -> 20 | H19: =+'Análisis (2)'!K86 -> Circulatorio | I19: =+'Análisis (2)'!L86 -> 32
A20: =+'Análisis (2)'!K8 -> Tiroides | B20: =+'Análisis (2)'!L8 -> 20 | D20: =+'Análisis (2)'!K31 -> Sinusitis | E20: =+'Análisis (2)'!L31 -> 12 | H20: =+'Análisis (2)'!K87 -> Consulta general | I20: =+'Análisis (2)'!L87 -> 12
A21: =+'Análisis (2)'!K9 -> Asma y Rinitis | B21: =+'Análisis (2)'!L9 -> 20 | D21: =+'Análisis (2)'!K32 -> Migraña | E21: =+'Análisis (2)'!L32 -> 8 | H21: =+'Análisis (2)'!K88 -> Dermatológico | I21: =+'Análisis (2)'!L88 -> 12
A22: =+'Análisis (2)'!K10 -> Hipertensión | B22: =+'Análisis (2)'!L10 -> 16 | D22: =+'Análisis (2)'!K33 -> Reflujo gastroesofágico | E22: =+'Análisis (2)'!L33 -> 8 | H22: =+'Análisis (2)'!K89 -> Gastrointestinal | I22: =+'Análisis (2)'!L89 -> 16
A23: =+'Análisis (2)'!K11 -> Hipotiroidismo | B23: =+'Análisis (2)'!L11 -> 16 | D23: =+'Análisis (2)'!K34 -> Picadura de insecto | E23: =+'Análisis (2)'!L34 -> 8 | H23: =+'Análisis (2)'!K90 -> Geniunitario | I23: =+'Análisis (2)'!L90 -> 24
B30: Monto promedio Consulta | M30: Días promedio de Incapacidad
B33: =+GETPIVOTDATA("Monto de la consulta",'Análisis (2)'!$A$5) -> 52915.226 | M33: =+GETPIVOTDATA("Días",'Análisis (2)'!$A$13) -> 3.64
A40: Conclusión:
A41: En el mes de Junio la mayor cantidad de pacientes atendidos fueron del sector público, las enfermedades más frecuentes que presentaron están relacionadas con padecimientos mentales: Transtorno de bipolaridad, Migraña, Hipertensión y Osteoporosis. Estos padecimientos a su vez se relacionan con un diagnóstico macro con afectaciones al sistea circulatorio, gastronintestinal y geniunitario, cabe destacar que en este caso la mayoría de las atenciones están relacionadas con la consulta general. Asimismo, los trabajadores que pertenecen al área de Gerencia y Recursos Humanos son los que presentaron mayores porcentajes de grasa.En adición, cabe desctacar que el promedio de citas de personas incapacitadas ascendió a 4, y quienes necesitaron un servicio adicional principalmente se remitieron a rayos x y otras consultas adicionales. El monto prmedio de cada cita fue de aproximadamente 55 colones, siendo este mayor para el caso de las mujeres, trabajadores del sector privado .
